Workbook

Sheet Assumptions
A1: Tenbagger model: assumptions (edit the blue cells; everything else recalculates)
A2: Blue = input. Black = formula. Bear/Bull cells in black follow Base; type a value to override. Mirrors tenbagger/finance/assumptions.yaml (re-run model.py to refresh Python outputs).
A3: Section | B3: Key | C3: Driver | D3: Unit | E3: Base | F3: Bear | G3: Bull | H3: Source / why
A4: SWITCHES
A5: Switches | B5: ads_on | C5: In-app ads on the free tier | D5: toggle | E5: 1 | F5: =$E5 -> 1 | G5: =$E5 -> 1 | H5: Founder request. Never shown to Pro. [U]
A6: Switches | B6: affiliate_on | C6: Affiliate offers (education-adjacent only, no credit) | D6: toggle | E6: 1 | F6: =$E6 -> 1 | G6: =$E6 -> 1 | H6: Founder request. Brand guardrail PS §5: never reward trading. [U]
A7: Switches | B7: b2b_on | C7: B2B / Edu licences (Classroom Pro, campus) | D7: toggle | E7: 0 | F7: =$E7 -> 0 | G7: =$E7 -> 0 | H7: PS §4: 'Edu (later)'. Off by default.
A8: Switches | B8: llm_on | C8: AI tutor enabled (v2) | D8: toggle | E8: 1 | F8: =$E8 -> 1 | G8: =$E8 -> 1 | H8: PS idea #21; v2 feature
A9: Switches | B9: plaid_on | C9: Bank / brokerage linking (Plaid) enabled | D9: toggle | E9: 1 | F9: =$E9 -> 1 | G9: =$E9 -> 1 | H9: MH §5 Option C: free = 1 bank, Pro = unlimited
A10: Switches | B10: founder_salary_on | C10: Pay founder salary | D10: toggle | E10: 0 | F10: =$E10 -> 0 | G10: =$E10 -> 0 | H10: BENCHMARKS §C excludes founder pay; $5k/mo 'ramen' hurdle shown separately
A11: Switches | B11: soc2_on | C11: SOC 2 programme (needed only for B2B) | D11: toggle | E11: 0 | F11: =$E11 -> 0 | G11: =$E11 -> 0 | H11: [U] Off until a B2B buyer asks
A12: ACQUISITION
A13: Acquisition | B13: organic_installs_m1 | C13: Organic installs (SEO / ASO / social), month 1 | D13: count | E13: 1050 | F13: 560 | G13: 2100 | H13: BENCHMARKS C1 base 1,500 total m1 x 70% non-paid share; [S54] Stock Analysis SEO; [S35] Finelo ~2.1k/day
A14: Acquisition | B14: organic_growth | C14: Organic installs growth, month over month | D14: pct | E14: 0.07 | F14: 0.04 | G14: 0.09 | H14: BENCHMARKS C1 (7% base; author judgment)
A15: Acquisition | B15: referral_installs_per_mau | C15: Referral installs per prior-month MAU | D15: x | E15: 0.015 | F15: 0.008 | G15: 0.03 | H15: [U] author. Share cards (PS idea #2); Robinhood referral waitlist [S62]
A16: Acquisition | B16: creator_start_month | C16: Creator sponsorships start (month) | D16: month | E16: 4 | F16: =$E16 -> 4 | G16: =$E16 -> 4 | H16: [U] after onboarding is tuned (PS §7 gates)
A17: Acquisition | B17: creator_budget_m1 | C17: Creator spend in start month | D17: usd | E17: 500 | F17: 300 | G17: 1000 | H17: [U] author; Brilliant's main channel [S27]
A18: Acquisition | B18: creator_budget_growth | C18: Creator spend growth, month over month | D18: pct | E18: 0.05 | F18: 0.03 | G18: 0.07 | H18: [U] author
A19: Acquisition | B19: creator_cpi | C19: Creator cost per install | D19: usd_c | E19: 8 | F19: 12 | G19: 5 | H19: [S20][U] $40-80 CPM x ~0.5% view-to-install = ~$10 CPI; base assumes CPA-style deals
A20: Acquisition | B20: asa_start_month | C20: Apple Search Ads start (month) | D20: month | E20: 1 | F20: =$E20 -> 1 | G20: =$E20 -> 1 | H20: [U]
A21: Acquisition | B21: asa_budget_m1 | C21: Apple Search Ads spend in start month | D21: usd | E21: 500 | F21: =$E21 -> 500 | G21: 1000 | H21: [U] test budget; PS §7 ads tests $300-500
A22: Acquisition | B22: asa_budget_growth | C22: ASA spend growth, month over month | D22: pct | E22: 0.03 | F22: 0 | G22: 0.06 | H22: [U] kept small: paid LTV/CAC < 1 in BENCHMARKS B4
A23: Acquisition | B23: asa_cpi | C23: Apple Search Ads cost per install | D23: usd_c | E23: 6 | F23: 9 | G23: 4 | H23: [S17][S] Finance CPA $13.28, all-category $3.76; [S18][U] Education CPT ~$1.24. Base bids education keywords
A24: ENGAGEMENT
A25: Engagement | B25: activation_rate | C25: Installs that activate (finish first lesson) | D25: pct | E25: 0.65 | F25: 0.55 | G25: 0.75 | H25: PS §7 W8 target 150 of 200 (75%) invited testers; public installs lower [U]
A26: Engagement | B26: d30_retention | C26: Free installs still active the following month (D30) | D26: pct | E26: 0.12 | F26: 0.06 | G26: 0.2 | H26: [S85][U] finance D30 2-6%; PS §7 gate D30 >= 7%. Habit product assumed above median
A27: Engagement | B27: retained_decay | C27: Monthly decay of the retained free pool | D27: pct | E27: 0.08 | F27: 0.12 | G27: 0.06 | H27: BENCHMARKS C1 uses 7%/mo decay
A28: CONVERSION
A29: Conversion | B29: trial_start_rate | C29: Trial / paywall starts as share of activated users | D29: pct | E29: 0.1 | F29: 0.08 | G29: 0.14 | H29: PS §7 gate: trial starts >= 8% of activated
A30: Conversion | B30: trial_to_paid | C30: Trial-to-paid | D30: pct | E30: 0.38 | F30: 0.33 | G30: 0.4 | H30: [S13][S] 37.4% for 5-9 day trials; PS gate >= 25%
A31: Conversion | B31: mix_monthly | C31: New payers choosing monthly plan | D31: pct | E31: 0.35 | F31: 0.4 | G31: 0.3 | H31: BENCHMARKS B2: 60% annual among monthly+annual
A32: Conversion | B32: mix_annual | C32: New payers choosing annual plan (student = remainder) | D32: pct | E32: 0.5 | F32: 0.45 | G32: 0.55 | H32: BENCHMARKS B2; annual plans retain best [S14]
A33: Conversion | B33: pass_rate | C33: Recruiting Pass purchases per activated user | D33: pct | E33: 0.004 | F33: 0.002 | G33: 0.008 | H33: PS §7 gate: >= 5 purchases per ~100 student testers; students ~ a third of users [U]
A34: PRICING
A35: Pricing | B35: price_monthly | C35: Pro monthly price | D35: usd_c | E35: 12.99 | F35: 9.99 | G35: 14.99 | H35: PS §4; BENCHMARKS C1 base; Monarch/Copilot $13-15 [S30][S31]
A36: Pricing | B36: price_annual | C36: Pro annual price | D36: usd_c | E36: 79.99 | F36: 59.99 | G36: 99.99 | H36: PS §4; Stock Analysis $79 [S56]; Monarch $99.99 [S30]
A37: Pricing | B37: price_student | C37: Student annual price (.edu verified) | D37: usd_c | E37: 39.99 | F37: =$E37 -> 39.99 | G37: =$E37 -> 39.99 | H37: PS §4 (~50% off, Spotify Student norm)
A38: Pricing | B38: price_pass | C38: Recruiting Pass, one-time (4 months) | D38: usd_c | E38: 49 | F38: =$E38 -> 49 | G38: =$E38 -> 49 | H38: PS §4 (10% of WSP/BIWS [S69][S70])
A39: Pricing | B39: store_fee | C39: App store commission | D39: pct | E39: 0.15 | F39: =$E39 -> 0.15 | G39: =$E39 -> 0.15 | H39: [S83][S] Apple Small Business Program < $1M proceeds; Google 15% on subscriptions
A40: Pricing | B40: refund_rate | C40: Refunds as share of gross in-app sales | D40: pct | E40: 0.02 | F40: 0.03 | G40: 0.015 | H40: [U] author estimate; PS pricing rules (no weekly traps) limit refunds
...

Sheet Monthly_Base
A1: Tenbagger: Base case, monthly (USD). All cells are formulas driven by the Assumptions sheet.
A2: Month | C2: 1 | D2: 2 | E2: 3 | F2: 4 | G2: 5 | H2: 6 | I2: 7 | J2: 8 | K2: 9 | L2: 10 | M2: 11 | N2: 12 | O2: 13 | P2: 14 | Q2: 15 | R2: 16 | S2: 17 | T2: 18 | U2: 19 | V2: 20 | W2: 21 | X2: 22 | Y2: 23 | Z2: 24 | AA2: 25 | AB2: 26 | AC2: 27 | AD2: 28 | AE2: 29 | AF2: 30 | AG2: 31 | AH2: 32 | AI2: 33 | AJ2: 34 | AK2: 35 | AL2: 36
A3: Fiscal year | C3: 1 | D3: 1 | E3: 1 | F3: 1 | G3: 1 | H3: 1 | I3: 1 | J3: 1 | K3: 1 | L3: 1 | M3: 1 | N3: 1 | O3: 2 | P3: 2 | Q3: 2 | R3: 2 | S3: 2 | T3: 2 | U3: 2 | V3: 2 | W3: 2 | X3: 2 | Y3: 2 | Z3: 2 | AA3: 3 | AB3: 3 | AC3: 3 | AD3: 3 | AE3: 3 | AF3: 3 | AG3: 3 | AH3: 3 | AI3: 3 | AJ3: 3 | AK3: 3 | AL3: 3
A4: Calendar month | C4: Jan-27 | D4: Feb-27 | E4: Mar-27 | F4: Apr-27 | G4: May-27 | H4: Jun-27 | I4: Jul-27 | J4: Aug-27 | K4: Sep-27 | L4: Oct-27 | M4: Nov-27 | N4: Dec-27 | O4: Jan-28 | P4: Feb-28 | Q4: Mar-28 | R4: Apr-28 | S4: May-28 | T4: Jun-28 | U4: Jul-28 | V4: Aug-28 | W4: Sep-28 | X4: Oct-28 | Y4: Nov-28 | Z4: Dec-28 | AA4: Jan-29 | AB4: Feb-29 | AC4: Mar-29 | AD4: Apr-29 | AE4: May-29 | AF4: Jun-29 | AG4: Jul-29 | AH4: Aug-29 | AI4: Sep-29 | AJ4: Oct-29 | AK4: Nov-29 | AL4: Dec-29
A5: ACQUISITION
A6: Installs: organic / SEO / ASO | B6: inst_org | C6: =(Assumptions!$E$13*((1+Assumptions!$E$14)^(C$2-1))) -> 1050 | D6: =(Assumptions!$E$13*((1+Assumptions!$E$14)^(D$2-1))) -> 1123.5 | E6: =(Assumptions!$E$13*((1+Assumptions!$E$14)^(E$2-1))) -> 1202.145 | F6: =(Assumptions!$E$13*((1+Assumptions!$E$14)^(F$2-1))) -> 1286.2951 | G6: =(Assumptions!$E$13*((1+Assumptions!$E$14)^(G$2-1))) -> 1376.3358 | H6: =(Assumptions!$E$13*((1+Assumptions!$E$14)^(H$2-1))) -> 1472.6793 | I6: =(Assumptions!$E$13*((1+Assumptions!$E$14)^(I$2-1))) -> 1575.7669 | J6: =(Assumptions!$E$13*((1+Assumptions!$E$14)^(J$2-1))) -> 1686.0706 | ... AL6: =(Assumptions!$E$13*((1+Assumptions!$E$14)^(AL$2-1))) -> 11210.411
A7: Installs: referral (x prior-month MAU) | B7: inst_ref | C7: =(Assumptions!$E$15*0) -> 0 | D7: =(Assumptions!$E$15*C36) -> 17 | E7: =(Assumptions!$E$15*D36) -> 20.784337 | F7: =(Assumptions!$E$15*E36) -> 24.468231 | G7: =(Assumptions!$E$15*F36) -> 29.175122 | H7: =(Assumptions!$E$15*G36) -> 33.244648 | I7: =(Assumptions!$E$15*H36) -> 37.431646 | J7: =(Assumptions!$E$15*I36) -> 41.766536 | K7: =(Assumptions!$E$15*J36) -> 46.270942 | ... AL7: =(Assumptions!$E$15*AK36) -> 334.27625
A8: Creator spend | B8: spend_creators | C8: =IF((C$2>=Assumptions!$E$16),(Assumptions!$E$17*((1+Assumptions!$E$18)^(C$2-Assumptions!$E$16))),0) -> 0 | D8: =IF((D$2>=Assumptions!$E$16),(Assumptions!$E$17*((1+Assumptions!$E$18)^(D$2-Assumptions!$E$16))),0) -> 0 | E8: =IF((E$2>=Assumptions!$E$16),(Assumptions!$E$17*((1+Assumptions!$E$18)^(E$2-Assumptions!$E$16))),0) -> 0 | F8: =IF((F$2>=Assumptions!$E$16),(Assumptions!$E$17*((1+Assumptions!$E$18)^(F$2-Assumptions!$E$16))),0) -> 500 | G8: =IF((G$2>=Assumptions!$E$16),(Assumptions!$E$17*((1+Assumptions!$E$18)^(G$2-Assumptions!$E$16))),0) -> 525 | H8: =IF((H$2>=Assumptions!$E$16),(Assumptions!$E$17*((1+Assumptions!$E$18)^(H$2-Assumptions!$E$16))),0) -> 551.25 | I8: =IF((I$2>=Assumptions!$E$16),(Assumptions!$E$17*((1+Assumptions!$E$18)^(I$2-Assumptions!$E$16))),0) -> 578.8125 | J8: =IF((J$2>=Assumptions!$E$16),(Assumptions!$E$17*((1+Assumptions!$E$18)^(J$2-Assumptions!$E$16))),0) -> 607.75312 | ... AL8: =IF((AL$2>=Assumptions!$E$16),(Assumptions!$E$17*((1+Assumptions!$E$18)^(AL$2-Assumptions!$E$16))),0) -> 2382.4707
A9: Installs: creators | B9: inst_creators | C9: =IF(Assumptions!$E$19=0,0,C8/Assumptions!$E$19) -> 0 | D9: =IF(Assumptions!$E$19=0,0,D8/Assumptions!$E$19) -> 0 | E9: =IF(Assumptions!$E$19=0,0,E8/Assumptions!$E$19) -> 0 | F9: =IF(Assumptions!$E$19=0,0,F8/Assumptions!$E$19) -> 62.5 | G9: =IF(Assumptions!$E$19=0,0,G8/Assumptions!$E$19) -> 65.625 | H9: =IF(Assumptions!$E$19=0,0,H8/Assumptions!$E$19) -> 68.90625 | I9: =IF(Assumptions!$E$19=0,0,I8/Assumptions!$E$19) -> 72.351562 | J9: =IF(Assumptions!$E$19=0,0,J8/Assumptions!$E$19) -> 75.969141 | ... AL9: =IF(Assumptions!$E$19=0,0,AL8/Assumptions!$E$19) -> 297.80884
A10: Apple Search Ads spend | B10: spend_asa | C10: =IF((C$2>=Assumptions!$E$20),(Assumptions!$E$21*((1+Assumptions!$E$22)^(C$2-Assumptions!$E$20))),0) -> 500 | D10: =IF((D$2>=Assumptions!$E$20),(Assumptions!$E$21*((1+Assumptions!$E$22)^(D$2-Assumptions!$E$20))),0) -> 515 | E10: =IF((E$2>=Assumptions!$E$20),(Assumptions!$E$21*((1+Assumptions!$E$22)^(E$2-Assumptions!$E$20))),0) -> 530.45 | F10: =IF((F$2>=Assumptions!$E$20),(Assumptions!$E$21*((1+Assumptions!$E$22)^(F$2-Assumptions!$E$20))),0) -> 546.3635 | G10: =IF((G$2>=Assumptions!$E$20),(Assumptions!$E$21*((1+Assumptions!$E$22)^(G$2-Assumptions!$E$20))),0) -> 562.75441 | H10: =IF((H$2>=Assumptions!$E$20),(Assumptions!$E$21*((1+Assumptions!$E$22)^(H$2-Assumptions!$E$20))),0) -> 579.63704 | I10: =IF((I$2>=Assumptions!$E$20),(Assumptions!$E$21*((1+Assumptions!$E$22)^(I$2-Assumptions!$E$20))),0) -> 597.02615 | J10: =IF((J$2>=Assumptions!$E$20),(Assumptions!$E$21*((1+Assumptions!$E$22)^(J$2-Assumptions!$E$20))),0) -> 614.93693 | ... AL10: =IF((AL$2>=Assumptions!$E$20),(Assumptions!$E$21*((1+Assumptions!$E$22)^(AL$2-Assumptions!$E$20))),0) -> 1406.9312
A11: Installs: paid Apple Search Ads | B11: inst_asa | C11: =IF(Assumptions!$E$23=0,0,C10/Assumptions!$E$23) -> 83.333333 | D11: =IF(Assumptions!$E$23=0,0,D10/Assumptions!$E$23) -> 85.833333 | E11: =IF(Assumptions!$E$23=0,0,E10/Assumptions!$E$23) -> 88.408333 | F11: =IF(Assumptions!$E$23=0,0,F10/Assumptions!$E$23) -> 91.060583 | G11: =IF(Assumptions!$E$23=0,0,G10/Assumptions!$E$23) -> 93.792401 | H11: =IF(Assumptions!$E$23=0,0,H10/Assumptions!$E$23) -> 96.606173 | I11: =IF(Assumptions!$E$23=0,0,I10/Assumptions!$E$23) -> 99.504358 | J11: =IF(Assumptions!$E$23=0,0,J10/Assumptions!$E$23) -> 102.48949 | ... AL11: =IF(Assumptions!$E$23=0,0,AL10/Assumptions!$E$23) -> 234.48854
A12: Total installs | B12: inst_total | C12: =(((C6+C7)+C9)+C11) -> 1133.3333 | D12: =(((D6+D7)+D9)+D11) -> 1226.3333 | E12: =(((E6+E7)+E9)+E11) -> 1311.3377 | F12: =(((F6+F7)+F9)+F11) -> 1464.324 | G12: =(((G6+G7)+G9)+G11) -> 1564.9283 | H12: =(((H6+H7)+H9)+H11) -> 1671.4364 | I12: =(((I6+I7)+I9)+I11) -> 1785.0544 | J12: =(((J6+J7)+J9)+J11) -> 1906.2957 | ... AL12: =(((AL6+AL7)+AL9)+AL11) -> 12076.984
A14: FUNNEL (free -> trial -> paid)
A15: Activated users | B15: activated | C15: =(C12*Assumptions!$E$25) -> 736.66667 | D15: =(D12*Assumptions!$E$25) -> 797.11667 | E15: =(E12*Assumptions!$E$25) -> 852.36949 | F15: =(F12*Assumptions!$E$25) -> 951.81058 | G15: =(G12*Assumptions!$E$25) -> 1017.2034 | H15: =(H12*Assumptions!$E$25) -> 1086.4337 | I15: =(I12*Assumptions!$E$25) -> 1160.2854 | J15: =(J12*Assumptions!$E$25) -> 1239.0922 | ... AL15: =(AL12*Assumptions!$E$25) -> 7850.0397
A16: Trial / paywall starts | B16: trial_starts | C16: =(C15*Assumptions!$E$29) -> 73.666667 | D16: =(D15*Assumptions!$E$29) -> 79.711667 | E16: =(E15*Assumptions!$E$29) -> 85.236949 | F16: =(F15*Assumptions!$E$29) -> 95.181058 | G16: =(G15*Assumptions!$E$29) -> 101.72034 | H16: =(H15*Assumptions!$E$29) -> 108.64337 | I16: =(I15*Assumptions!$E$29) -> 116.02854 | J16: =(J15*Assumptions!$E$29) -> 123.90922 | ... AL16: =(AL15*Assumptions!$E$29) -> 785.00397
A17: New paid subscribers | B17: new_paid | C17: =(C16*Assumptions!$E$30) -> 27.993333 | D17: =(D16*Assumptions!$E$30) -> 30.290433 | E17: =(E16*Assumptions!$E$30) -> 32.39004 | F17: =(F16*Assumptions!$E$30) -> 36.168802 | G17: =(G16*Assumptions!$E$30) -> 38.65373 | H17: =(H16*Assumptions!$E$30) -> 41.284479 | I17: =(I16*Assumptions!$E$30) -> 44.090845 | J17: =(J16*Assumptions!$E$30) -> 47.085504 | ... AL17: =(AL16*Assumptions!$E$30) -> 298.30151
A18: of which monthly plan | B18: new_monthly | C18: =(C17*Assumptions!$E$31) -> 9.7976667 | D18: =(D17*Assumptions!$E$31) -> 10.601652 | E18: =(E17*Assumptions!$E$31) -> 11.336514 | F18: =(F17*Assumptions!$E$31) -> 12.659081 | G18: =(G17*Assumptions!$E$31) -> 13.528805 | H18: =(H17*Assumptions!$E$31) -> 14.449568 | I18: =(I17*Assumptions!$E$31) -> 15.431796 | J18: =(J17*Assumptions!$E$31) -> 16.479926 | ... AL18: =(AL17*Assumptions!$E$31) -> 104.40553
A19: of which annual plan | B19: new_annual | C19: =(C17*Assumptions!$E$32) -> 13.996667 | D19: =(D17*Assumptions!$E$32) -> 15.145217 | E19: =(E17*Assumptions!$E$32) -> 16.19502 | F19: =(F17*Assumptions!$E$32) -> 18.084401 | G19: =(G17*Assumptions!$E$32) -> 19.326865 | H19: =(H17*Assumptions!$E$32) -> 20.642239 | I19: =(I17*Assumptions!$E$32) -> 22.045422 | J19: =(J17*Assumptions!$E$32) -> 23.542752 | ... AL19: =(AL17*Assumptions!$E$32) -> 149.15075
A20: of which student plan | B20: new_student | C20: =(C17*Assumptions!$E$109) -> 4.199 | D20: =(D17*Assumptions!$E$109) -> 4.543565 | E20: =(E17*Assumptions!$E$109) -> 4.8585061 | F20: =(F17*Assumptions!$E$109) -> 5.4253203 | G20: =(G17*Assumptions!$E$109) -> 5.7980595 | H20: =(H17*Assumptions!$E$109) -> 6.1926718 | I20: =(I17*Assumptions!$E$109) -> 6.6136267 | J20: =(J17*Assumptions!$E$109) -> 7.0628256 | ... AL20: =(AL17*Assumptions!$E$109) -> 44.745226
A21: Recruiting Pass purchases (one-time) | B21: pass_sales | C21: =(C15*Assumptions!$E$33) -> 2.9466667 | D21: =(D15*Assumptions!$E$33) -> 3.1884667 | E21: =(E15*Assumptions!$E$33) -> 3.4094779 | F21: =(F15*Assumptions!$E$33) -> 3.8072423 | G21: =(G15*Assumptions!$E$33) -> 4.0688137 | H21: =(H15*Assumptions!$E$33) -> 4.3457346 | I21: =(I15*Assumptions!$E$33) -> 4.6411415 | J21: =(J15*Assumptions!$E$33) -> 4.9563689 | ... AL21: =(AL15*Assumptions!$E$33) -> 31.400159
A23: SUBSCRIBERS
A24: Monthly-plan subscribers (end of month) | B24: subs_monthly | C24: =((0*(1-Assumptions!$E$110))+C18) -> 9.7976667 | D24: =((C24*(1-Assumptions!$E$110))+D18) -> 19.054312 | E24: =((D24*(1-Assumptions!$E$110))+E18) -> 27.775083 | F24: =((E24*(1-Assumptions!$E$110))+F18) -> 36.621249 | G24: =((F24*(1-Assumptions!$E$110))+G18) -> 45.122753 | H24: =((G24*(1-Assumptions!$E$110))+H18) -> 53.377948 | I24: =((H24*(1-Assumptions!$E$110))+I18) -> 61.482112 | J24: =((I24*(1-Assumptions!$E$110))+J18) -> 69.521881 | K24: =((J24*(1-Assumptions!$E$110))+K18) -> 77.576649 | ... AL24: =((AK24*(1-Assumptions!$E$110))+AL18) -> 541.86091
A25: Annual plans billed (new + renewals) | B25: bill_annual | C25: =(C19+0) -> 13.996667 | D25: =(D19+0) -> 15.145217 | E25: =(E19+0) -> 16.19502 | F25: =(F19+0) -> 18.084401 | G25: =(G19+0) -> 19.326865 | H25: =(H19+0) -> 20.642239 | I25: =(I19+0) -> 22.045422 | J25: =(J19+0) -> 23.542752 | ... N25: =(N19+0) -> 30.613343 | O25: =(O19+(Assumptions!$E$43*C25)) -> 38.86307 | P25: =(P19+(Assumptions!$E$43*D25)) -> 41.586248 | Q25: =(Q19+(Assumptions!$E$43*E25)) -> 44.416986 | R25: =(R19+(Assumptions!$E$43*F25)) -> 47.77967 | S25: =(S19+(Assumptions!$E$43*G25)) -> 51.029917 | T25: =(T19+(Assumptions!$E$43*H25)) -> 54.497315 | U25: =(U19+(Assumptions!$E$43*I25)) -> 58.201316 | V25: =(V19+(Assumptions!$E$43*J25)) -> 62.158483 | ... AL25: =(AL19+(Assumptions!$E$43*Z25)) -> 184.82354
A26: Annual-plan subscribers (billed in last 12 months) | B26: subs_annual | C26: =SUM(C25:C25) -> 13.996667 | D26: =SUM(C25:D25) -> 29.141883 | E26: =SUM(C25:E25) -> 45.336904 | F26: =SUM(C25:F25) -> 63.421305 | G26: =SUM(C25:G25) -> 82.748169 | H26: =SUM(C25:H25) -> 103.39041 | I26: =SUM(C25:I25) -> 125.43583 | J26: =SUM(C25:J25) -> 148.97858 | K26: =SUM(C25:K25) -> 174.11946 | L26: =SUM(C25:L25) -> 200.96633 | M26: =SUM(C25:M25) -> 229.63467 | N26: =SUM(C25:N25) -> 260.24801 | O26: =SUM(D25:O25) -> 285.11442 | P26: =SUM(E25:P25) -> 311.55545 | Q26: =SUM(F25:Q25) -> 339.77741 | R26: =SUM(G25:R25) -> 369.47268 | S26: =SUM(H25:S25) -> 401.17573 | T26: =SUM(I25:T25) -> 435.03081 | U26: =SUM(J25:U25) -> 471.1867 | ... AL26: =SUM(AA25:AL25) -> 1581.1018
A27: Student plans billed (new + renewals) | B27: bill_student | C27: =(C20+0) -> 4.199 | D27: =(D20+0) -> 4.543565 | E27: =(E20+0) -> 4.8585061 | F27: =(F20+0) -> 5.4253203 | G27: =(G20+0) -> 5.7980595 | H27: =(H20+0) -> 6.1926718 | I27: =(I20+0) -> 6.6136267 | J27: =(J20+0) -> 7.0628256 | ... N27: =(N20+0) -> 9.184003 | O27: =(O20+(Assumptions!$E$44*C27)) -> 11.276812 | P27: =(P20+(Assumptions!$E$44*D27)) -> 12.06241 | Q27: =(Q20+(Assumptions!$E$44*E27)) -> 12.882972 | R27: =(R20+(Assumptions!$E$44*F27)) -> 13.840197 | S27: =(S20+(Assumptions!$E$44*G27)) -> 14.781352 | T27: =(T20+(Assumptions!$E$44*H27)) -> 15.785661 | U27: =(U20+(Assumptions!$E$44*I27)) -> 16.858555 | V27: =(V20+(Assumptions!$E$44*J27)) -> 18.004828 | ... AL27: =(AL20+(Assumptions!$E$44*Z27)) -> 52.946237
A28: Student-plan subscribers | B28: subs_student | C28: =SUM(C27:C27) -> 4.199 | D28: =SUM(C27:D27) -> 8.742565 | E28: =SUM(C27:E27) -> 13.601071 | F28: =SUM(C27:F27) -> 19.026391 | G28: =SUM(C27:G27) -> 24.824451 | H28: =SUM(C27:H27) -> 31.017123 | I28: =SUM(C27:I27) -> 37.630749 | J28: =SUM(C27:J27) -> 44.693575 | K28: =SUM(C27:K27) -> 52.235837 | L28: =SUM(C27:L27) -> 60.2899 | M28: =SUM(C27:M27) -> 68.890401 | N28: =SUM(C27:N27) -> 78.074404 | O28: =SUM(D27:O27) -> 85.152216 | P28: =SUM(E27:P27) -> 92.671061 | Q28: =SUM(F27:Q27) -> 100.69553 | R28: =SUM(G27:R27) -> 109.1104 | S28: =SUM(H27:S27) -> 118.0937 | T28: =SUM(I27:T27) -> 127.68668 | U28: =SUM(J27:U27) -> 137.93161 | ... AL28: =SUM(AA27:AL27) -> 452.94009
A29: Paid subscribers (end of month) | B29: subs_paid | C29: =((C24+C26)+C28) -> 27.993333 | D29: =((D24+D26)+D28) -> 56.93876 | E29: =((E24+E26)+E28) -> 86.713058 | F29: =((F24+F26)+F28) -> 119.06894 | G29: =((G24+G26)+G28) -> 152.69537 | H29: =((H24+H26)+H28) -> 187.78548 | I29: =((I24+I26)+I28) -> 224.54869 | J29: =((J24+J26)+J28) -> 263.19404 | ... AL29: =((AL24+AL26)+AL28) -> 2575.9028
A30: Gross in-app billings, cash basis (= RevenueCat MTR) | B30: bill_gross | C30: =((((C24*Assumptions!$E$35)+(C25*Assumptions!$E$36))+(C27*Assumptions!$E$37))+(C21*Assumptions!$E$38)) -> 1559.1697 | D30: =((((D24*Assumptions!$E$35)+(D25*Assumptions!$E$36))+(D27*Assumptions!$E$37))+(D21*Assumptions!$E$38)) -> 1796.9134 | E30: =((((E24*Assumptions!$E$35)+(E25*Assumptions!$E$36))+(E27*Assumptions!$E$37))+(E21*Assumptions!$E$38)) -> 2017.5941 | F30: =((((F24*Assumptions!$E$35)+(F25*Assumptions!$E$36))+(F27*Assumptions!$E$37))+(F21*Assumptions!$E$38)) -> 2325.7947 | G30: =((((G24*Assumptions!$E$35)+(G25*Assumptions!$E$36))+(G27*Assumptions!$E$37))+(G21*Assumptions!$E$38)) -> 2563.3368 | H30: =((((H24*Assumptions!$E$35)+(H25*Assumptions!$E$36))+(H27*Assumptions!$E$37))+(H21*Assumptions!$E$38)) -> 2805.1382 | I30: =((((I24*Assumptions!$E$35)+(I25*Assumptions!$E$36))+(I27*Assumptions!$E$37))+(I21*Assumptions!$E$38)) -> 3053.9608 | J30: =((((J24*Assumptions!$E$35)+(J25*Assumptions!$E$36))+(J27*Assumptions!$E$37))+(J21*Assumptions!$E$38)) -> 3311.5784 | ... AL30: =((((AL24*Assumptions!$E$35)+(AL25*Assumptions!$E$36))+(AL27*Assumptions!$E$37))+(AL21*Assumptions!$E$38)) -> 25478.736
A32: ACTIVE USERS
A33: New free users this month | B33: free_new | C33: =(C12-C17) -> 1105.34 | D33: =(D12-D17) -> 1196.0429 | E33: =(E12-E17) -> 1278.9476 | F33: =(F12-F17) -> 1428.1552 | G33: =(G12-G17) -> 1526.2746 | H33: =(H12-H17) -> 1630.1519 | I33: =(I12-I17) -> 1740.9636 | J33: =(J12-J17) -> 1859.2102 | ... AL33: =(AL12-AL17) -> 11778.683
A34: Retained free users from earlier months | B34: free_pool | C34: =((0*(1-Assumptions!$E$27))+(0*Assumptions!$E$26)) -> 0 | D34: =((C34*(1-Assumptions!$E$27))+(C33*Assumptions!$E$26)) -> 132.6408 | E34: =((D34*(1-Assumptions!$E$27))+(D33*Assumptions!$E$26)) -> 265.55468 | F34: =((E34*(1-Assumptions!$E$27))+(E33*Assumptions!$E$26)) -> 397.78402 | G34: =((F34*(1-Assumptions!$E$27))+(F33*Assumptions!$E$26)) -> 537.33992 | H34: =((G34*(1-Assumptions!$E$27))+(G33*Assumptions!$E$26)) -> 677.50568 | I34: =((H34*(1-Assumptions!$E$27))+(H33*Assumptions!$E$26)) -> 818.92346 | J34: =((I34*(1-Assumptions!$E$27))+(I33*Assumptions!$E$26)) -> 962.32521 | K34: =((J34*(1-Assumptions!$E$27))+(J33*Assumptions!$E$26)) -> 1108.4444 | ... AL34: =((AK34*(1-Assumptions!$E$27))+(AK33*Assumptions!$E$26)) -> 9469.7587
A35: Free MAU | B35: mau_free | C35: =(C33+C34) -> 1105.34 | D35: =(D33+D34) -> 1328.6837 | E35: =(E33+E34) -> 1544.5023 | F35: =(F33+F34) -> 1825.9392 | G35: =(G33+G34) -> 2063.6145 | H35: =(H33+H34) -> 2307.6576 | I35: =(I33+I34) -> 2559.887 | J35: =(J33+J34) -> 2821.5354 | ... AL35: =(AL33+AL34) -> 21248.441
A36: Total MAU (free + paid) | B36: mau_total | C36: =(C35+C29) -> 1133.3333 | D36: =(D35+D29) -> 1385.6225 | E36: =(E35+E29) -> 1631.2154 | F36: =(F35+F29) -> 1945.0081 | G36: =(G35+G29) -> 2216.3099 | H36: =(H35+H29) -> 2495.4431 | I36: =(I35+I29) -> 2784.4357 | J36: =(J35+J29) -> 3084.7295 | ... AL36: =(AL35+AL29) -> 23824.344
A37: Paid subscribers / MAU | B37: paid_share | C37: =IF(C36=0,0,C29/C36) -> 0.0247 | D37: =IF(D36=0,0,D29/D36) -> 0.04109255 | E37: =IF(E36=0,0,E29/E36) -> 0.053158559 | F37: =IF(F36=0,0,F29/F36) -> 0.06121771 | G37: =IF(G36=0,0,G29/G36) -> 0.06889622 | H37: =IF(H36=0,0,H29/H36) -> 0.075251358 | I37: =IF(I36=0,0,I29/I36) -> 0.080644236 | J37: =IF(J36=0,0,J29/J36) -> 0.085321595 | ... AL37: =IF(AL36=0,0,AL29/AL36) -> 0.10812062
A39: ADS, AFFILIATE, B2B AND LINKING VOLUMES
A40: Free MAU seeing ads | B40: ad_mau | C40: =IF(AND((Assumptions!$E$5=1),(C$2>=Assumptions!$E$46)),(C35*Assumptions!$E$47),0) -> 0 | D40: =IF(AND((Assumptions!$E$5=1),(D$2>=Assumptions!$E$46)),(D35*Assumptions!$E$47),0) -> 0 | E40: =IF(AND((Assumptions!$E$5=1),(E$2>=Assumptions!$E$46)),(E35*Assumptions!$E$47),0) -> 0 | F40: =IF(AND((Assumptions!$E$5=1),(F$2>=Assumptions!$E$46)),(F35*Assumptions!$E$47),0) -> 1278.1574 | G40: =IF(AND((Assumptions!$E$5=1),(G$2>=Assumptions!$E$46)),(G35*Assumptions!$E$47),0) -> 1444.5302 | H40: =IF(AND((Assumptions!$E$5=1),(H$2>=Assumptions!$E$46)),(H35*Assumptions!$E$47),0) -> 1615.3603 | I40: =IF(AND((Assumptions!$E$5=1),(I$2>=Assumptions!$E$46)),(I35*Assumptions!$E$47),0) -> 1791.9209 | J40: =IF(AND((Assumptions!$E$5=1),(J$2>=Assumptions!$E$46)),(J35*Assumptions!$E$47),0) -> 1975.0748 | ... AL40: =IF(AND((Assumptions!$E$5=1),(AL$2>=Assumptions!$E$46)),(AL35*Assumptions!$E$47),0) -> 14873.909
A41: Ad impressions: article / lesson end | B41: imps_article | C41: =(C40*Assumptions!$E$48) -> 0 | D41: =(D40*Assumptions!$E$48) -> 0 | E41: =(E40*Assumptions!$E$48) -> 0 | F41: =(F40*Assumptions!$E$48) -> 10225.259 | G41: =(G40*Assumptions!$E$48) -> 11556.241 | H41: =(H40*Assumptions!$E$48) -> 12922.883 | I41: =(I40*Assumptions!$E$48) -> 14335.367 | J41: =(J40*Assumptions!$E$48) -> 15800.598 | ... AL41: =(AL40*Assumptions!$E$48) -> 118991.27
A42: Ad impressions: screener native | B42: imps_screener | C42: =(C40*Assumptions!$E$49) -> 0 | D42: =(D40*Assumptions!$E$49) -> 0 | E42: =(E40*Assumptions!$E$49) -> 0 | F42: =(F40*Assumptions!$E$49) -> 5112.6297 | G42: =(G40*Assumptions!$E$49) -> 5778.1207 | H42: =(H40*Assumptions!$E$49) -> 6461.4413 | I42: =(I40*Assumptions!$E$49) -> 7167.6837 | J42: =(J40*Assumptions!$E$49) -> 7900.2992 | ... AL42: =(AL40*Assumptions!$E$49) -> 59495.636
A43: Ad impressions: opt-in rewarded | B43: imps_rewarded | C43: =(C40*Assumptions!$E$50) -> 0 | D43: =(D40*Assumptions!$E$50) -> 0 | E43: =(E40*Assumptions!$E$50) -> 0 | F43: =(F40*Assumptions!$E$50) -> 1278.1574 | G43: =(G40*Assumptions!$E$50) -> 1444.5302 | H43: =(H40*Assumptions!$E$50) -> 1615.3603 | I43: =(I40*Assumptions!$E$50) -> 1791.9209 | J43: =(J40*Assumptions!$E$50) -> 1975.0748 | ... AL43: =(AL40*Assumptions!$E$50) -> 14873.909
A44: Affiliate clicks | B44: aff_clicks | C44: =IF(AND((Assumptions!$E$6=1),(C$2>=Assumptions!$E$56)),((C36/1000)*Assumptions!$E$57),0) -> 0 | D44: =IF(AND((Assumptions!$E$6=1),(D$2>=Assumptions!$E$56)),((D36/1000)*Assumptions!$E$57),0) -> 0 | E44: =IF(AND((Assumptions!$E$6=1),(E$2>=Assumptions!$E$56)),((E36/1000)*Assumptions!$E$57),0) -> 0 | F44: =IF(AND((Assumptions!$E$6=1),(F$2>=Assumptions!$E$56)),((F36/1000)*Assumptions!$E$57),0) -> 0 | G44: =IF(AND((Assumptions!$E$6=1),(G$2>=Assumptions!$E$56)),((G36/1000)*Assumptions!$E$57),0) -> 0 | H44: =IF(AND((Assumptions!$E$6=1),(H$2>=Assumptions!$E$56)),((H36/1000)*Assumptions!$E$57),0) -> 0 | I44: =IF(AND((Assumptions!$E$6=1),(I$2>=Assumptions!$E$56)),((I36/1000)*Assumptions!$E$57),0) -> 13.922179 | J44: =IF(AND((Assumptions!$E$6=1),(J$2>=Assumptions!$E$56)),((J36/1000)*Assumptions!$E$57),0) -> 15.423647 | ... AL44: =IF(AND((Assumptions!$E$6=1),(AL$2>=Assumptions!$E$56)),((AL36/1000)*Assumptions!$E$57),0) -> 119.12172
...

Sheet Monthly_Bear
A1: Tenbagger: Bear case, monthly (USD). All cells are formulas driven by the Assumptions sheet.
A2: Month | C2: 1 | D2: 2 | E2: 3 | F2: 4 | G2: 5 | H2: 6 | I2: 7 | J2: 8 | K2: 9 | L2: 10 | M2: 11 | N2: 12 | O2: 13 | P2: 14 | Q2: 15 | R2: 16 | S2: 17 | T2: 18 | U2: 19 | V2: 20 | W2: 21 | X2: 22 | Y2: 23 | Z2: 24 | AA2: 25 | AB2: 26 | AC2: 27 | AD2: 28 | AE2: 29 | AF2: 30 | AG2: 31 | AH2: 32 | AI2: 33 | AJ2: 34 | AK2: 35 | AL2: 36
A3: Fiscal year | C3: 1 | D3: 1 | E3: 1 | F3: 1 | G3: 1 | H3: 1 | I3: 1 | J3: 1 | K3: 1 | L3: 1 | M3: 1 | N3: 1 | O3: 2 | P3: 2 | Q3: 2 | R3: 2 | S3: 2 | T3: 2 | U3: 2 | V3: 2 | W3: 2 | X3: 2 | Y3: 2 | Z3: 2 | AA3: 3 | AB3: 3 | AC3: 3 | AD3: 3 | AE3: 3 | AF3: 3 | AG3: 3 | AH3: 3 | AI3: 3 | AJ3: 3 | AK3: 3 | AL3: 3
A4: Calendar month | C4: Jan-27 | D4: Feb-27 | E4: Mar-27 | F4: Apr-27 | G4: May-27 | H4: Jun-27 | I4: Jul-27 | J4: Aug-27 | K4: Sep-27 | L4: Oct-27 | M4: Nov-27 | N4: Dec-27 | O4: Jan-28 | P4: Feb-28 | Q4: Mar-28 | R4: Apr-28 | S4: May-28 | T4: Jun-28 | U4: Jul-28 | V4: Aug-28 | W4: Sep-28 | X4: Oct-28 | Y4: Nov-28 | Z4: Dec-28 | AA4: Jan-29 | AB4: Feb-29 | AC4: Mar-29 | AD4: Apr-29 | AE4: May-29 | AF4: Jun-29 | AG4: Jul-29 | AH4: Aug-29 | AI4: Sep-29 | AJ4: Oct-29 | AK4: Nov-29 | AL4: Dec-29
A5: ACQUISITION
A6: Installs: organic / SEO / ASO | B6: inst_org | C6: =(Assumptions!$F$13*((1+Assumptions!$F$14)^(C$2-1))) -> 560 | D6: =(Assumptions!$F$13*((1+Assumptions!$F$14)^(D$2-1))) -> 582.4 | E6: =(Assumptions!$F$13*((1+Assumptions!$F$14)^(E$2-1))) -> 605.696 | F6: =(Assumptions!$F$13*((1+Assumptions!$F$14)^(F$2-1))) -> 629.92384 | G6: =(Assumptions!$F$13*((1+Assumptions!$F$14)^(G$2-1))) -> 655.12079 | H6: =(Assumptions!$F$13*((1+Assumptions!$F$14)^(H$2-1))) -> 681.32563 | I6: =(Assumptions!$F$13*((1+Assumptions!$F$14)^(I$2-1))) -> 708.57865 | J6: =(Assumptions!$F$13*((1+Assumptions!$F$14)^(J$2-1))) -> 736.9218 | ... AL6: =(Assumptions!$F$13*((1+Assumptions!$F$14)^(AL$2-1))) -> 2209.8098
A7: Installs: referral (x prior-month MAU) | B7: inst_ref | C7: =(Assumptions!$F$15*0) -> 0 | D7: =(Assumptions!$F$15*C36) -> 4.9244444 | E7: =(Assumptions!$F$15*D36) -> 5.5006251 | F7: =(Assumptions!$F$15*E36) -> 6.0259326 | G7: =(Assumptions!$F$15*F36) -> 6.7362293 | H7: =(Assumptions!$F$15*G36) -> 7.2577393 | I7: =(Assumptions!$F$15*H36) -> 7.7695165 | J7: =(Assumptions!$F$15*I36) -> 8.2761196 | K7: =(Assumptions!$F$15*J36) -> 8.780502 | ... AL7: =(Assumptions!$F$15*AK36) -> 27.037483
A8: Creator spend | B8: spend_creators | C8: =IF((C$2>=Assumptions!$F$16),(Assumptions!$F$17*((1+Assumptions!$F$18)^(C$2-Assumptions!$F$16))),0) -> 0 | D8: =IF((D$2>=Assumptions!$F$16),(Assumptions!$F$17*((1+Assumptions!$F$18)^(D$2-Assumptions!$F$16))),0) -> 0 | E8: =IF((E$2>=Assumptions!$F$16),(Assumptions!$F$17*((1+Assumptions!$F$18)^(E$2-Assumptions!$F$16))),0) -> 0 | F8: =IF((F$2>=Assumptions!$F$16),(Assumptions!$F$17*((1+Assumptions!$F$18)^(F$2-Assumptions!$F$16))),0) -> 300 | G8: =IF((G$2>=Assumptions!$F$16),(Assumptions!$F$17*((1+Assumptions!$F$18)^(G$2-Assumptions!$F$16))),0) -> 309 | H8: =IF((H$2>=Assumptions!$F$16),(Assumptions!$F$17*((1+Assumptions!$F$18)^(H$2-Assumptions!$F$16))),0) -> 318.27 | I8: =IF((I$2>=Assumptions!$F$16),(Assumptions!$F$17*((1+Assumptions!$F$18)^(I$2-Assumptions!$F$16))),0) -> 327.8181 | J8: =IF((J$2>=Assumptions!$F$16),(Assumptions!$F$17*((1+Assumptions!$F$18)^(J$2-Assumptions!$F$16))),0) -> 337.65264 | ... AL8: =IF((AL$2>=Assumptions!$F$16),(Assumptions!$F$17*((1+Assumptions!$F$18)^(AL$2-Assumptions!$F$16))),0) -> 772.52483
A9: Installs: creators | B9: inst_creators | C9: =IF(Assumptions!$F$19=0,0,C8/Assumptions!$F$19) -> 0 | D9: =IF(Assumptions!$F$19=0,0,D8/Assumptions!$F$19) -> 0 | E9: =IF(Assumptions!$F$19=0,0,E8/Assumptions!$F$19) -> 0 | F9: =IF(Assumptions!$F$19=0,0,F8/Assumptions!$F$19) -> 25 | G9: =IF(Assumptions!$F$19=0,0,G8/Assumptions!$F$19) -> 25.75 | H9: =IF(Assumptions!$F$19=0,0,H8/Assumptions!$F$19) -> 26.5225 | I9: =IF(Assumptions!$F$19=0,0,I8/Assumptions!$F$19) -> 27.318175 | J9: =IF(Assumptions!$F$19=0,0,J8/Assumptions!$F$19) -> 28.13772 | ... AL9: =IF(Assumptions!$F$19=0,0,AL8/Assumptions!$F$19) -> 64.377069
A10: Apple Search Ads spend | B10: spend_asa | C10: =IF((C$2>=Assumptions!$F$20),(Assumptions!$F$21*((1+Assumptions!$F$22)^(C$2-Assumptions!$F$20))),0) -> 500 | D10: =IF((D$2>=Assumptions!$F$20),(Assumptions!$F$21*((1+Assumptions!$F$22)^(D$2-Assumptions!$F$20))),0) -> 500 | E10: =IF((E$2>=Assumptions!$F$20),(Assumptions!$F$21*((1+Assumptions!$F$22)^(E$2-Assumptions!$F$20))),0) -> 500 | F10: =IF((F$2>=Assumptions!$F$20),(Assumptions!$F$21*((1+Assumptions!$F$22)^(F$2-Assumptions!$F$20))),0) -> 500 | G10: =IF((G$2>=Assumptions!$F$20),(Assumptions!$F$21*((1+Assumptions!$F$22)^(G$2-Assumptions!$F$20))),0) -> 500 | H10: =IF((H$2>=Assumptions!$F$20),(Assumptions!$F$21*((1+Assumptions!$F$22)^(H$2-Assumptions!$F$20))),0) -> 500 | I10: =IF((I$2>=Assumptions!$F$20),(Assumptions!$F$21*((1+Assumptions!$F$22)^(I$2-Assumptions!$F$20))),0) -> 500 | J10: =IF((J$2>=Assumptions!$F$20),(Assumptions!$F$21*((1+Assumptions!$F$22)^(J$2-Assumptions!$F$20))),0) -> 500 | ... AL10: =IF((AL$2>=Assumptions!$F$20),(Assumptions!$F$21*((1+Assumptions!$F$22)^(AL$2-Assumptions!$F$20))),0) -> 500
A11: Installs: paid Apple Search Ads | B11: inst_asa | C11: =IF(Assumptions!$F$23=0,0,C10/Assumptions!$F$23) -> 55.555556 | D11: =IF(Assumptions!$F$23=0,0,D10/Assumptions!$F$23) -> 55.555556 | E11: =IF(Assumptions!$F$23=0,0,E10/Assumptions!$F$23) -> 55.555556 | F11: =IF(Assumptions!$F$23=0,0,F10/Assumptions!$F$23) -> 55.555556 | G11: =IF(Assumptions!$F$23=0,0,G10/Assumptions!$F$23) -> 55.555556 | H11: =IF(Assumptions!$F$23=0,0,H10/Assumptions!$F$23) -> 55.555556 | I11: =IF(Assumptions!$F$23=0,0,I10/Assumptions!$F$23) -> 55.555556 | J11: =IF(Assumptions!$F$23=0,0,J10/Assumptions!$F$23) -> 55.555556 | ... AL11: =IF(Assumptions!$F$23=0,0,AL10/Assumptions!$F$23) -> 55.555556
A12: Total installs | B12: inst_total | C12: =(((C6+C7)+C9)+C11) -> 615.55556 | D12: =(((D6+D7)+D9)+D11) -> 642.88 | E12: =(((E6+E7)+E9)+E11) -> 666.75218 | F12: =(((F6+F7)+F9)+F11) -> 716.50533 | G12: =(((G6+G7)+G9)+G11) -> 743.16258 | H12: =(((H6+H7)+H9)+H11) -> 770.66142 | I12: =(((I6+I7)+I9)+I11) -> 799.2219 | J12: =(((J6+J7)+J9)+J11) -> 828.89119 | ... AL12: =(((AL6+AL7)+AL9)+AL11) -> 2356.7799
A14: FUNNEL (free -> trial -> paid)
A15: Activated users | B15: activated | C15: =(C12*Assumptions!$F$25) -> 338.55556 | D15: =(D12*Assumptions!$F$25) -> 353.584 | E15: =(E12*Assumptions!$F$25) -> 366.7137 | F15: =(F12*Assumptions!$F$25) -> 394.07793 | G15: =(G12*Assumptions!$F$25) -> 408.73942 | H15: =(H12*Assumptions!$F$25) -> 423.86378 | I15: =(I12*Assumptions!$F$25) -> 439.57204 | J15: =(J12*Assumptions!$F$25) -> 455.89016 | ... AL15: =(AL12*Assumptions!$F$25) -> 1296.229
A16: Trial / paywall starts | B16: trial_starts | C16: =(C15*Assumptions!$F$29) -> 27.084444 | D16: =(D15*Assumptions!$F$29) -> 28.28672 | E16: =(E15*Assumptions!$F$29) -> 29.337096 | F16: =(F15*Assumptions!$F$29) -> 31.526234 | G16: =(G15*Assumptions!$F$29) -> 32.699153 | H16: =(H15*Assumptions!$F$29) -> 33.909102 | I16: =(I15*Assumptions!$F$29) -> 35.165763 | J16: =(J15*Assumptions!$F$29) -> 36.471212 | ... AL16: =(AL15*Assumptions!$F$29) -> 103.69832
A17: New paid subscribers | B17: new_paid | C17: =(C16*Assumptions!$F$30) -> 8.9378667 | D17: =(D16*Assumptions!$F$30) -> 9.3346176 | E17: =(E16*Assumptions!$F$30) -> 9.6812417 | F17: =(F16*Assumptions!$F$30) -> 10.403657 | G17: =(G16*Assumptions!$F$30) -> 10.790721 | H17: =(H16*Assumptions!$F$30) -> 11.190004 | I17: =(I16*Assumptions!$F$30) -> 11.604702 | J17: =(J16*Assumptions!$F$30) -> 12.0355 | ... AL17: =(AL16*Assumptions!$F$30) -> 34.220445
A18: of which monthly plan | B18: new_monthly | C18: =(C17*Assumptions!$F$31) -> 3.5751467 | D18: =(D17*Assumptions!$F$31) -> 3.733847 | E18: =(E17*Assumptions!$F$31) -> 3.8724967 | F18: =(F17*Assumptions!$F$31) -> 4.1614629 | G18: =(G17*Assumptions!$F$31) -> 4.3162883 | H18: =(H17*Assumptions!$F$31) -> 4.4760015 | I18: =(I17*Assumptions!$F$31) -> 4.6418808 | J18: =(J17*Assumptions!$F$31) -> 4.8142 | ... AL18: =(AL17*Assumptions!$F$31) -> 13.688178
A19: of which annual plan | B19: new_annual | C19: =(C17*Assumptions!$F$32) -> 4.02204 | D19: =(D17*Assumptions!$F$32) -> 4.2005779 | E19: =(E17*Assumptions!$F$32) -> 4.3565587 | F19: =(F17*Assumptions!$F$32) -> 4.6816458 | G19: =(G17*Assumptions!$F$32) -> 4.8558243 | H19: =(H17*Assumptions!$F$32) -> 5.0355017 | I19: =(I17*Assumptions!$F$32) -> 5.2221159 | J19: =(J17*Assumptions!$F$32) -> 5.415975 | ... AL19: =(AL17*Assumptions!$F$32) -> 15.3992
A20: of which student plan | B20: new_student | C20: =(C17*Assumptions!$F$109) -> 1.34068 | D20: =(D17*Assumptions!$F$109) -> 1.4001926 | E20: =(E17*Assumptions!$F$109) -> 1.4521862 | F20: =(F17*Assumptions!$F$109) -> 1.5605486 | G20: =(G17*Assumptions!$F$109) -> 1.6186081 | H20: =(H17*Assumptions!$F$109) -> 1.6785006 | I20: =(I17*Assumptions!$F$109) -> 1.7407053 | J20: =(J17*Assumptions!$F$109) -> 1.805325 | ... AL20: =(AL17*Assumptions!$F$109) -> 5.1330667
A21: Recruiting Pass purchases (one-time) | B21: pass_sales | C21: =(C15*Assumptions!$F$33) -> 0.67711111 | D21: =(D15*Assumptions!$F$33) -> 0.707168 | E21: =(E15*Assumptions!$F$33) -> 0.7334274 | F21: =(F15*Assumptions!$F$33) -> 0.78815586 | G21: =(G15*Assumptions!$F$33) -> 0.81747884 | H21: =(H15*Assumptions!$F$33) -> 0.84772756 | I21: =(I15*Assumptions!$F$33) -> 0.87914409 | J21: =(J15*Assumptions!$F$33) -> 0.91178031 | ... AL21: =(AL15*Assumptions!$F$33) -> 2.5924579
A23: SUBSCRIBERS
A24: Monthly-plan subscribers (end of month) | B24: subs_monthly | C24: =((0*(1-Assumptions!$F$110))+C18) -> 3.5751467 | D24: =((C24*(1-Assumptions!$F$110))+D18) -> 6.6722014 | E24: =((D24*(1-Assumptions!$F$110))+E18) -> 9.3562694 | F24: =((E24*(1-Assumptions!$F$110))+F18) -> 11.851227 | G24: =((F24*(1-Assumptions!$F$110))+G18) -> 14.056617 | H24: =((G24*(1-Assumptions!$F$110))+H18) -> 16.028904 | I24: =((H24*(1-Assumptions!$F$110))+I18) -> 17.815774 | J24: =((I24*(1-Assumptions!$F$110))+J18) -> 19.456692 | K24: =((J24*(1-Assumptions!$F$110))+K18) -> 20.984369 | ... AL24: =((AK24*(1-Assumptions!$F$110))+AL18) -> 65.594024
A25: Annual plans billed (new + renewals) | B25: bill_annual | C25: =(C19+0) -> 4.02204 | D25: =(D19+0) -> 4.2005779 | E25: =(E19+0) -> 4.3565587 | F25: =(F19+0) -> 4.6816458 | G25: =(G19+0) -> 4.8558243 | H25: =(H19+0) -> 5.0355017 | I25: =(I19+0) -> 5.2221159 | J25: =(J19+0) -> 5.415975 | ... N25: =(N19+0) -> 6.2701889 | O25: =(O19+(Assumptions!$F$43*C25)) -> 7.7398769 | P25: =(P19+(Assumptions!$F$43*D25)) -> 8.0386693 | Q25: =(Q19+(Assumptions!$F$43*E25)) -> 8.3401619 | R25: =(R19+(Assumptions!$F$43*F25)) -> 8.7035891 | S25: =(S19+(Assumptions!$F$43*G25)) -> 9.0311044 | T25: =(T19+(Assumptions!$F$43*H25)) -> 9.3711537 | U25: =(U19+(Assumptions!$F$43*I25)) -> 9.7246156 | V25: =(V19+(Assumptions!$F$43*J25)) -> 10.092039 | ... AL25: =(AL19+(Assumptions!$F$43*Z25)) -> 18.995089
A26: Annual-plan subscribers (billed in last 12 months) | B26: subs_annual | C26: =SUM(C25:C25) -> 4.02204 | D26: =SUM(C25:D25) -> 8.2226179 | E26: =SUM(C25:E25) -> 12.579177 | F26: =SUM(C25:F25) -> 17.260822 | G26: =SUM(C25:G25) -> 22.116647 | H26: =SUM(C25:H25) -> 27.152148 | I26: =SUM(C25:I25) -> 32.374264 | J26: =SUM(C25:J25) -> 37.790239 | K26: =SUM(C25:K25) -> 43.407628 | L26: =SUM(C25:L25) -> 49.234301 | M26: =SUM(C25:M25) -> 55.278462 | N26: =SUM(C25:N25) -> 61.548651 | O26: =SUM(D25:O25) -> 65.266487 | P26: =SUM(E25:P25) -> 69.104579 | Q26: =SUM(F25:Q25) -> 73.088182 | R26: =SUM(G25:R25) -> 77.110125 | S26: =SUM(H25:S25) -> 81.285405 | T26: =SUM(I25:T25) -> 85.621057 | U26: =SUM(J25:U25) -> 90.123557 | ... AL26: =SUM(AA25:AL25) -> 186.75498
A27: Student plans billed (new + renewals) | B27: bill_student | C27: =(C20+0) -> 1.34068 | D27: =(D20+0) -> 1.4001926 | E27: =(E20+0) -> 1.4521862 | F27: =(F20+0) -> 1.5605486 | G27: =(G20+0) -> 1.6186081 | H27: =(H20+0) -> 1.6785006 | I27: =(I20+0) -> 1.7407053 | J27: =(J20+0) -> 1.805325 | ... N27: =(N20+0) -> 2.090063 | O27: =(O20+(Assumptions!$F$44*C27)) -> 2.5035402 | P27: =(P20+(Assumptions!$F$44*D27)) -> 2.5997455 | Q27: =(Q20+(Assumptions!$F$44*E27)) -> 2.6972793 | R27: =(R20+(Assumptions!$F$44*F27)) -> 2.8122451 | S27: =(S20+(Assumptions!$F$44*G27)) -> 2.9181075 | T27: =(T20+(Assumptions!$F$44*H27)) -> 3.0280434 | U27: =(U20+(Assumptions!$F$44*I27)) -> 3.1423183 | V27: =(V20+(Assumptions!$F$44*J27)) -> 3.2611094 | ... AL27: =(AL20+(Assumptions!$F$44*Z27)) -> 6.0793662
A28: Student-plan subscribers | B28: subs_student | C28: =SUM(C27:C27) -> 1.34068 | D28: =SUM(C27:D27) -> 2.7408726 | E28: =SUM(C27:E27) -> 4.1930589 | F28: =SUM(C27:F27) -> 5.7536075 | G28: =SUM(C27:G27) -> 7.3722156 | H28: =SUM(C27:H27) -> 9.0507162 | I28: =SUM(C27:I27) -> 10.791421 | J28: =SUM(C27:J27) -> 12.596746 | K28: =SUM(C27:K27) -> 14.469209 | L28: =SUM(C27:L27) -> 16.411434 | M28: =SUM(C27:M27) -> 18.426154 | N28: =SUM(C27:N27) -> 20.516217 | O28: =SUM(D27:O27) -> 21.679077 | P28: =SUM(E27:P27) -> 22.87863 | Q28: =SUM(F27:Q27) -> 24.123723 | R28: =SUM(G27:R27) -> 25.375419 | S28: =SUM(H27:S27) -> 26.674919 | T28: =SUM(I27:T27) -> 28.024462 | U28: =SUM(J27:U27) -> 29.426075 | ... AL28: =SUM(AA27:AL27) -> 59.767025
A29: Paid subscribers (end of month) | B29: subs_paid | C29: =((C24+C26)+C28) -> 8.9378667 | D29: =((D24+D26)+D28) -> 17.635692 | E29: =((E24+E26)+E28) -> 26.128505 | F29: =((F24+F26)+F28) -> 34.865657 | G29: =((G24+G26)+G28) -> 43.545479 | H29: =((H24+H26)+H28) -> 52.231769 | I29: =((I24+I26)+I28) -> 60.98146 | J29: =((J24+J26)+J28) -> 69.843678 | ... AL29: =((AL24+AL26)+AL28) -> 312.11603
A30: Gross in-app billings, cash basis (= RevenueCat MTR) | B30: bill_gross | C30: =((((C24*Assumptions!$F$35)+(C25*Assumptions!$F$36))+(C27*Assumptions!$F$37))+(C21*Assumptions!$F$38)) -> 363.79013 | D30: =((((D24*Assumptions!$F$35)+(D25*Assumptions!$F$36))+(D27*Assumptions!$F$37))+(D21*Assumptions!$F$38)) -> 409.2929 | E30: =((((E24*Assumptions!$F$35)+(E25*Assumptions!$F$36))+(E27*Assumptions!$F$37))+(E21*Assumptions!$F$38)) -> 448.82996 | F30: =((((F24*Assumptions!$F$35)+(F25*Assumptions!$F$36))+(F27*Assumptions!$F$37))+(F21*Assumptions!$F$38)) -> 500.27167 | G30: =((((G24*Assumptions!$F$35)+(G25*Assumptions!$F$36))+(G27*Assumptions!$F$37))+(G21*Assumptions!$F$38)) -> 536.5111 | H30: =((((H24*Assumptions!$F$35)+(H25*Assumptions!$F$36))+(H27*Assumptions!$F$37))+(H21*Assumptions!$F$38)) -> 570.87039 | I30: =((((I24*Assumptions!$F$35)+(I25*Assumptions!$F$36))+(I27*Assumptions!$F$37))+(I21*Assumptions!$F$38)) -> 603.94318 | J30: =((((J24*Assumptions!$F$35)+(J25*Assumptions!$F$36))+(J27*Assumptions!$F$37))+(J21*Assumptions!$F$38)) -> 636.14888 | ... AL30: =((((AL24*Assumptions!$F$35)+(AL25*Assumptions!$F$36))+(AL27*Assumptions!$F$37))+(AL21*Assumptions!$F$38)) -> 2164.944
A32: ACTIVE USERS
A33: New free users this month | B33: free_new | C33: =(C12-C17) -> 606.61769 | D33: =(D12-D17) -> 633.54538 | E33: =(E12-E17) -> 657.07094 | F33: =(F12-F17) -> 706.10167 | G33: =(G12-G17) -> 732.37186 | H33: =(H12-H17) -> 759.47142 | I33: =(I12-I17) -> 787.6172 | J33: =(J12-J17) -> 816.85569 | ... AL33: =(AL12-AL17) -> 2322.5595
A34: Retained free users from earlier months | B34: free_pool | C34: =((0*(1-Assumptions!$F$27))+(0*Assumptions!$F$26)) -> 0 | D34: =((C34*(1-Assumptions!$F$27))+(C33*Assumptions!$F$26)) -> 36.397061 | E34: =((D34*(1-Assumptions!$F$27))+(D33*Assumptions!$F$26)) -> 70.042137 | F34: =((E34*(1-Assumptions!$F$27))+(E33*Assumptions!$F$26)) -> 101.06134 | G34: =((F34*(1-Assumptions!$F$27))+(F33*Assumptions!$F$26)) -> 131.30008 | H34: =((G34*(1-Assumptions!$F$27))+(G33*Assumptions!$F$26)) -> 159.48638 | I34: =((H34*(1-Assumptions!$F$27))+(H33*Assumptions!$F$26)) -> 185.9163 | J34: =((I34*(1-Assumptions!$F$27))+(I33*Assumptions!$F$26)) -> 210.86337 | K34: =((J34*(1-Assumptions!$F$27))+(J33*Assumptions!$F$26)) -> 234.57111 | ... AL34: =((AK34*(1-Assumptions!$F$27))+(AK33*Assumptions!$F$26)) -> 876.55155
A35: Free MAU | B35: mau_free | C35: =(C33+C34) -> 606.61769 | D35: =(D33+D34) -> 669.94244 | E35: =(E33+E34) -> 727.11308 | F35: =(F33+F34) -> 807.16301 | G35: =(G33+G34) -> 863.67193 | H35: =(H33+H34) -> 918.9578 | I35: =(I33+I34) -> 973.53349 | J35: =(J33+J34) -> 1027.7191 | ... AL35: =(AL33+AL34) -> 3199.111
A36: Total MAU (free + paid) | B36: mau_total | C36: =(C35+C29) -> 615.55556 | D36: =(D35+D29) -> 687.57814 | E36: =(E35+E29) -> 753.24158 | F36: =(F35+F29) -> 842.02866 | G36: =(G35+G29) -> 907.21741 | H36: =(H35+H29) -> 971.18956 | I36: =(I35+I29) -> 1034.515 | J36: =(J35+J29) -> 1097.5627 | ... AL36: =(AL35+AL29) -> 3511.2271
A37: Paid subscribers / MAU | B37: paid_share | C37: =IF(C36=0,0,C29/C36) -> 0.01452 | D37: =IF(D36=0,0,D29/D36) -> 0.025649 | E37: =IF(E36=0,0,E29/E36) -> 0.034688081 | F37: =IF(F36=0,0,F29/F36) -> 0.041406734 | G37: =IF(G36=0,0,G29/G36) -> 0.047998946 | H37: =IF(H36=0,0,H29/H36) -> 0.05378123 | I37: =IF(I36=0,0,I29/I36) -> 0.05894691 | J37: =IF(J36=0,0,J29/J36) -> 0.063635248 | ... AL37: =IF(AL36=0,0,AL29/AL36) -> 0.08889087
A39: ADS, AFFILIATE, B2B AND LINKING VOLUMES
A40: Free MAU seeing ads | B40: ad_mau | C40: =IF(AND((Assumptions!$F$5=1),(C$2>=Assumptions!$F$46)),(C35*Assumptions!$F$47),0) -> 0 | D40: =IF(AND((Assumptions!$F$5=1),(D$2>=Assumptions!$F$46)),(D35*Assumptions!$F$47),0) -> 0 | E40: =IF(AND((Assumptions!$F$5=1),(E$2>=Assumptions!$F$46)),(E35*Assumptions!$F$47),0) -> 0 | F40: =IF(AND((Assumptions!$F$5=1),(F$2>=Assumptions!$F$46)),(F35*Assumptions!$F$47),0) -> 484.2978 | G40: =IF(AND((Assumptions!$F$5=1),(G$2>=Assumptions!$F$46)),(G35*Assumptions!$F$47),0) -> 518.20316 | H40: =IF(AND((Assumptions!$F$5=1),(H$2>=Assumptions!$F$46)),(H35*Assumptions!$F$47),0) -> 551.37468 | I40: =IF(AND((Assumptions!$F$5=1),(I$2>=Assumptions!$F$46)),(I35*Assumptions!$F$47),0) -> 584.1201 | J40: =IF(AND((Assumptions!$F$5=1),(J$2>=Assumptions!$F$46)),(J35*Assumptions!$F$47),0) -> 616.63144 | ... AL40: =IF(AND((Assumptions!$F$5=1),(AL$2>=Assumptions!$F$46)),(AL35*Assumptions!$F$47),0) -> 1919.4666
A41: Ad impressions: article / lesson end | B41: imps_article | C41: =(C40*Assumptions!$F$48) -> 0 | D41: =(D40*Assumptions!$F$48) -> 0 | E41: =(E40*Assumptions!$F$48) -> 0 | F41: =(F40*Assumptions!$F$48) -> 2421.489 | G41: =(G40*Assumptions!$F$48) -> 2591.0158 | H41: =(H40*Assumptions!$F$48) -> 2756.8734 | I41: =(I40*Assumptions!$F$48) -> 2920.6005 | J41: =(J40*Assumptions!$F$48) -> 3083.1572 | ... AL41: =(AL40*Assumptions!$F$48) -> 9597.3331
A42: Ad impressions: screener native | B42: imps_screener | C42: =(C40*Assumptions!$F$49) -> 0 | D42: =(D40*Assumptions!$F$49) -> 0 | E42: =(E40*Assumptions!$F$49) -> 0 | F42: =(F40*Assumptions!$F$49) -> 968.59561 | G42: =(G40*Assumptions!$F$49) -> 1036.4063 | H42: =(H40*Assumptions!$F$49) -> 1102.7494 | I42: =(I40*Assumptions!$F$49) -> 1168.2402 | J42: =(J40*Assumptions!$F$49) -> 1233.2629 | ... AL42: =(AL40*Assumptions!$F$49) -> 3838.9333
A43: Ad impressions: opt-in rewarded | B43: imps_rewarded | C43: =(C40*Assumptions!$F$50) -> 0 | D43: =(D40*Assumptions!$F$50) -> 0 | E43: =(E40*Assumptions!$F$50) -> 0 | F43: =(F40*Assumptions!$F$50) -> 242.1489 | G43: =(G40*Assumptions!$F$50) -> 259.10158 | H43: =(H40*Assumptions!$F$50) -> 275.68734 | I43: =(I40*Assumptions!$F$50) -> 292.06005 | J43: =(J40*Assumptions!$F$50) -> 308.31572 | ... AL43: =(AL40*Assumptions!$F$50) -> 959.73331
A44: Affiliate clicks | B44: aff_clicks | C44: =IF(AND((Assumptions!$F$6=1),(C$2>=Assumptions!$F$56)),((C36/1000)*Assumptions!$F$57),0) -> 0 | D44: =IF(AND((Assumptions!$F$6=1),(D$2>=Assumptions!$F$56)),((D36/1000)*Assumptions!$F$57),0) -> 0 | E44: =IF(AND((Assumptions!$F$6=1),(E$2>=Assumptions!$F$56)),((E36/1000)*Assumptions!$F$57),0) -> 0 | F44: =IF(AND((Assumptions!$F$6=1),(F$2>=Assumptions!$F$56)),((F36/1000)*Assumptions!$F$57),0) -> 0 | G44: =IF(AND((Assumptions!$F$6=1),(G$2>=Assumptions!$F$56)),((G36/1000)*Assumptions!$F$57),0) -> 0 | H44: =IF(AND((Assumptions!$F$6=1),(H$2>=Assumptions!$F$56)),((H36/1000)*Assumptions!$F$57),0) -> 0 | I44: =IF(AND((Assumptions!$F$6=1),(I$2>=Assumptions!$F$56)),((I36/1000)*Assumptions!$F$57),0) -> 3.1035449 | J44: =IF(AND((Assumptions!$F$6=1),(J$2>=Assumptions!$F$56)),((J36/1000)*Assumptions!$F$57),0) -> 3.2926882 | ... AL44: =IF(AND((Assumptions!$F$6=1),(AL$2>=Assumptions!$F$56)),((AL36/1000)*Assumptions!$F$57),0) -> 10.533681
...

Sheet Monthly_Bull
A1: Tenbagger: Bull case, monthly (USD). All cells are formulas driven by the Assumptions sheet.
A2: Month | C2: 1 | D2: 2 | E2: 3 | F2: 4 | G2: 5 | H2: 6 | I2: 7 | J2: 8 | K2: 9 | L2: 10 | M2: 11 | N2: 12 | O2: 13 | P2: 14 | Q2: 15 | R2: 16 | S2: 17 | T2: 18 | U2: 19 | V2: 20 | W2: 21 | X2: 22 | Y2: 23 | Z2: 24 | AA2: 25 | AB2: 26 | AC2: 27 | AD2: 28 | AE2: 29 | AF2: 30 | AG2: 31 | AH2: 32 | AI2: 33 | AJ2: 34 | AK2: 35 | AL2: 36
A3: Fiscal year | C3: 1 | D3: 1 | E3: 1 | F3: 1 | G3: 1 | H3: 1 | I3: 1 | J3: 1 | K3: 1 | L3: 1 | M3: 1 | N3: 1 | O3: 2 | P3: 2 | Q3: 2 | R3: 2 | S3: 2 | T3: 2 | U3: 2 | V3: 2 | W3: 2 | X3: 2 | Y3: 2 | Z3: 2 | AA3: 3 | AB3: 3 | AC3: 3 | AD3: 3 | AE3: 3 | AF3: 3 | AG3: 3 | AH3: 3 | AI3: 3 | AJ3: 3 | AK3: 3 | AL3: 3
A4: Calendar month | C4: Jan-27 | D4: Feb-27 | E4: Mar-27 | F4: Apr-27 | G4: May-27 | H4: Jun-27 | I4: Jul-27 | J4: Aug-27 | K4: Sep-27 | L4: Oct-27 | M4: Nov-27 | N4: Dec-27 | O4: Jan-28 | P4: Feb-28 | Q4: Mar-28 | R4: Apr-28 | S4: May-28 | T4: Jun-28 | U4: Jul-28 | V4: Aug-28 | W4: Sep-28 | X4: Oct-28 | Y4: Nov-28 | Z4: Dec-28 | AA4: Jan-29 | AB4: Feb-29 | AC4: Mar-29 | AD4: Apr-29 | AE4: May-29 | AF4: Jun-29 | AG4: Jul-29 | AH4: Aug-29 | AI4: Sep-29 | AJ4: Oct-29 | AK4: Nov-29 | AL4: Dec-29
A5: ACQUISITION
A6: Installs: organic / SEO / ASO | B6: inst_org | C6: =(Assumptions!$G$13*((1+Assumptions!$G$14)^(C$2-1))) -> 2100 | D6: =(Assumptions!$G$13*((1+Assumptions!$G$14)^(D$2-1))) -> 2289 | E6: =(Assumptions!$G$13*((1+Assumptions!$G$14)^(E$2-1))) -> 2495.01 | F6: =(Assumptions!$G$13*((1+Assumptions!$G$14)^(F$2-1))) -> 2719.5609 | G6: =(Assumptions!$G$13*((1+Assumptions!$G$14)^(G$2-1))) -> 2964.3214 | H6: =(Assumptions!$G$13*((1+Assumptions!$G$14)^(H$2-1))) -> 3231.1103 | I6: =(Assumptions!$G$13*((1+Assumptions!$G$14)^(I$2-1))) -> 3521.9102 | J6: =(Assumptions!$G$13*((1+Assumptions!$G$14)^(J$2-1))) -> 3838.8822 | ... AL6: =(Assumptions!$G$13*((1+Assumptions!$G$14)^(AL$2-1))) -> 42869.333
A7: Installs: referral (x prior-month MAU) | B7: inst_ref | C7: =(Assumptions!$G$15*0) -> 0 | D7: =(Assumptions!$G$15*C36) -> 70.5 | E7: =(Assumptions!$G$15*D36) -> 95.106885 | F7: =(Assumptions!$G$15*E36) -> 119.88984 | G7: =(Assumptions!$G$15*F36) -> 152.03684 | H7: =(Assumptions!$G$15*G36) -> 181.73249 | I7: =(Assumptions!$G$15*H36) -> 213.13639 | J7: =(Assumptions!$G$15*I36) -> 246.53979 | K7: =(Assumptions!$G$15*J36) -> 282.16184 | ... AL7: =(Assumptions!$G$15*AK36) -> 3589.0952
A8: Creator spend | B8: spend_creators | C8: =IF((C$2>=Assumptions!$G$16),(Assumptions!$G$17*((1+Assumptions!$G$18)^(C$2-Assumptions!$G$16))),0) -> 0 | D8: =IF((D$2>=Assumptions!$G$16),(Assumptions!$G$17*((1+Assumptions!$G$18)^(D$2-Assumptions!$G$16))),0) -> 0 | E8: =IF((E$2>=Assumptions!$G$16),(Assumptions!$G$17*((1+Assumptions!$G$18)^(E$2-Assumptions!$G$16))),0) -> 0 | F8: =IF((F$2>=Assumptions!$G$16),(Assumptions!$G$17*((1+Assumptions!$G$18)^(F$2-Assumptions!$G$16))),0) -> 1000 | G8: =IF((G$2>=Assumptions!$G$16),(Assumptions!$G$17*((1+Assumptions!$G$18)^(G$2-Assumptions!$G$16))),0) -> 1070 | H8: =IF((H$2>=Assumptions!$G$16),(Assumptions!$G$17*((1+Assumptions!$G$18)^(H$2-Assumptions!$G$16))),0) -> 1144.9 | I8: =IF((I$2>=Assumptions!$G$16),(Assumptions!$G$17*((1+Assumptions!$G$18)^(I$2-Assumptions!$G$16))),0) -> 1225.043 | J8: =IF((J$2>=Assumptions!$G$16),(Assumptions!$G$17*((1+Assumptions!$G$18)^(J$2-Assumptions!$G$16))),0) -> 1310.796 | ... AL8: =IF((AL$2>=Assumptions!$G$16),(Assumptions!$G$17*((1+Assumptions!$G$18)^(AL$2-Assumptions!$G$16))),0) -> 8715.2708
A9: Installs: creators | B9: inst_creators | C9: =IF(Assumptions!$G$19=0,0,C8/Assumptions!$G$19) -> 0 | D9: =IF(Assumptions!$G$19=0,0,D8/Assumptions!$G$19) -> 0 | E9: =IF(Assumptions!$G$19=0,0,E8/Assumptions!$G$19) -> 0 | F9: =IF(Assumptions!$G$19=0,0,F8/Assumptions!$G$19) -> 200 | G9: =IF(Assumptions!$G$19=0,0,G8/Assumptions!$G$19) -> 214 | H9: =IF(Assumptions!$G$19=0,0,H8/Assumptions!$G$19) -> 228.98 | I9: =IF(Assumptions!$G$19=0,0,I8/Assumptions!$G$19) -> 245.0086 | J9: =IF(Assumptions!$G$19=0,0,J8/Assumptions!$G$19) -> 262.1592 | ... AL9: =IF(Assumptions!$G$19=0,0,AL8/Assumptions!$G$19) -> 1743.0542
A10: Apple Search Ads spend | B10: spend_asa | C10: =IF((C$2>=Assumptions!$G$20),(Assumptions!$G$21*((1+Assumptions!$G$22)^(C$2-Assumptions!$G$20))),0) -> 1000 | D10: =IF((D$2>=Assumptions!$G$20),(Assumptions!$G$21*((1+Assumptions!$G$22)^(D$2-Assumptions!$G$20))),0) -> 1060 | E10: =IF((E$2>=Assumptions!$G$20),(Assumptions!$G$21*((1+Assumptions!$G$22)^(E$2-Assumptions!$G$20))),0) -> 1123.6 | F10: =IF((F$2>=Assumptions!$G$20),(Assumptions!$G$21*((1+Assumptions!$G$22)^(F$2-Assumptions!$G$20))),0) -> 1191.016 | G10: =IF((G$2>=Assumptions!$G$20),(Assumptions!$G$21*((1+Assumptions!$G$22)^(G$2-Assumptions!$G$20))),0) -> 1262.477 | H10: =IF((H$2>=Assumptions!$G$20),(Assumptions!$G$21*((1+Assumptions!$G$22)^(H$2-Assumptions!$G$20))),0) -> 1338.2256 | I10: =IF((I$2>=Assumptions!$G$20),(Assumptions!$G$21*((1+Assumptions!$G$22)^(I$2-Assumptions!$G$20))),0) -> 1418.5191 | J10: =IF((J$2>=Assumptions!$G$20),(Assumptions!$G$21*((1+Assumptions!$G$22)^(J$2-Assumptions!$G$20))),0) -> 1503.6303 | ... AL10: =IF((AL$2>=Assumptions!$G$20),(Assumptions!$G$21*((1+Assumptions!$G$22)^(AL$2-Assumptions!$G$20))),0) -> 7686.0868
A11: Installs: paid Apple Search Ads | B11: inst_asa | C11: =IF(Assumptions!$G$23=0,0,C10/Assumptions!$G$23) -> 250 | D11: =IF(Assumptions!$G$23=0,0,D10/Assumptions!$G$23) -> 265 | E11: =IF(Assumptions!$G$23=0,0,E10/Assumptions!$G$23) -> 280.9 | F11: =IF(Assumptions!$G$23=0,0,F10/Assumptions!$G$23) -> 297.754 | G11: =IF(Assumptions!$G$23=0,0,G10/Assumptions!$G$23) -> 315.61924 | H11: =IF(Assumptions!$G$23=0,0,H10/Assumptions!$G$23) -> 334.55639 | I11: =IF(Assumptions!$G$23=0,0,I10/Assumptions!$G$23) -> 354.62978 | J11: =IF(Assumptions!$G$23=0,0,J10/Assumptions!$G$23) -> 375.90756 | ... AL11: =IF(Assumptions!$G$23=0,0,AL10/Assumptions!$G$23) -> 1921.5217
A12: Total installs | B12: inst_total | C12: =(((C6+C7)+C9)+C11) -> 2350 | D12: =(((D6+D7)+D9)+D11) -> 2624.5 | E12: =(((E6+E7)+E9)+E11) -> 2871.0169 | F12: =(((F6+F7)+F9)+F11) -> 3337.2047 | G12: =(((G6+G7)+G9)+G11) -> 3645.9775 | H12: =(((H6+H7)+H9)+H11) -> 3976.3792 | I12: =(((I6+I7)+I9)+I11) -> 4334.685 | J12: =(((J6+J7)+J9)+J11) -> 4723.4887 | ... AL12: =(((AL6+AL7)+AL9)+AL11) -> 50123.004
A14: FUNNEL (free -> trial -> paid)
A15: Activated users | B15: activated | C15: =(C12*Assumptions!$G$25) -> 1762.5 | D15: =(D12*Assumptions!$G$25) -> 1968.375 | E15: =(E12*Assumptions!$G$25) -> 2153.2627 | F15: =(F12*Assumptions!$G$25) -> 2502.9036 | G15: =(G12*Assumptions!$G$25) -> 2734.4831 | H15: =(H12*Assumptions!$G$25) -> 2982.2844 | I15: =(I12*Assumptions!$G$25) -> 3251.0138 | J15: =(J12*Assumptions!$G$25) -> 3542.6165 | ... AL15: =(AL12*Assumptions!$G$25) -> 37592.253
A16: Trial / paywall starts | B16: trial_starts | C16: =(C15*Assumptions!$G$29) -> 246.75 | D16: =(D15*Assumptions!$G$29) -> 275.5725 | E16: =(E15*Assumptions!$G$29) -> 301.45677 | F16: =(F15*Assumptions!$G$29) -> 350.4065 | G16: =(G15*Assumptions!$G$29) -> 382.82763 | H16: =(H15*Assumptions!$G$29) -> 417.51981 | I16: =(I15*Assumptions!$G$29) -> 455.14193 | J16: =(J15*Assumptions!$G$29) -> 495.96631 | ... AL16: =(AL15*Assumptions!$G$29) -> 5262.9154
A17: New paid subscribers | B17: new_paid | C17: =(C16*Assumptions!$G$30) -> 98.7 | D17: =(D16*Assumptions!$G$30) -> 110.229 | E17: =(E16*Assumptions!$G$30) -> 120.58271 | F17: =(F16*Assumptions!$G$30) -> 140.1626 | G17: =(G16*Assumptions!$G$30) -> 153.13105 | H17: =(H16*Assumptions!$G$30) -> 167.00793 | I17: =(I16*Assumptions!$G$30) -> 182.05677 | J17: =(J16*Assumptions!$G$30) -> 198.38653 | ... AL17: =(AL16*Assumptions!$G$30) -> 2105.1662
A18: of which monthly plan | B18: new_monthly | C18: =(C17*Assumptions!$G$31) -> 29.61 | D18: =(D17*Assumptions!$G$31) -> 33.0687 | E18: =(E17*Assumptions!$G$31) -> 36.174813 | F18: =(F17*Assumptions!$G$31) -> 42.04878 | G18: =(G17*Assumptions!$G$31) -> 45.939316 | H18: =(H17*Assumptions!$G$31) -> 50.102378 | I18: =(I17*Assumptions!$G$31) -> 54.617031 | J18: =(J17*Assumptions!$G$31) -> 59.515958 | ... AL18: =(AL17*Assumptions!$G$31) -> 631.54985
A19: of which annual plan | B19: new_annual | C19: =(C17*Assumptions!$G$32) -> 54.285 | D19: =(D17*Assumptions!$G$32) -> 60.62595 | E19: =(E17*Assumptions!$G$32) -> 66.32049 | F19: =(F17*Assumptions!$G$32) -> 77.08943 | G19: =(G17*Assumptions!$G$32) -> 84.222079 | H19: =(H17*Assumptions!$G$32) -> 91.854359 | I19: =(I17*Assumptions!$G$32) -> 100.13122 | J19: =(J17*Assumptions!$G$32) -> 109.11259 | ... AL19: =(AL17*Assumptions!$G$32) -> 1157.8414
A20: of which student plan | B20: new_student | C20: =(C17*Assumptions!$G$109) -> 14.805 | D20: =(D17*Assumptions!$G$109) -> 16.53435 | E20: =(E17*Assumptions!$G$109) -> 18.087406 | F20: =(F17*Assumptions!$G$109) -> 21.02439 | G20: =(G17*Assumptions!$G$109) -> 22.969658 | H20: =(H17*Assumptions!$G$109) -> 25.051189 | I20: =(I17*Assumptions!$G$109) -> 27.308516 | J20: =(J17*Assumptions!$G$109) -> 29.757979 | ... AL20: =(AL17*Assumptions!$G$109) -> 315.77492
A21: Recruiting Pass purchases (one-time) | B21: pass_sales | C21: =(C15*Assumptions!$G$33) -> 14.1 | D21: =(D15*Assumptions!$G$33) -> 15.747 | E21: =(E15*Assumptions!$G$33) -> 17.226101 | F21: =(F15*Assumptions!$G$33) -> 20.023228 | G21: =(G15*Assumptions!$G$33) -> 21.875865 | H21: =(H15*Assumptions!$G$33) -> 23.858275 | I21: =(I15*Assumptions!$G$33) -> 26.00811 | J21: =(J15*Assumptions!$G$33) -> 28.340932 | ... AL21: =(AL15*Assumptions!$G$33) -> 300.73802
A23: SUBSCRIBERS
A24: Monthly-plan subscribers (end of month) | B24: subs_monthly | C24: =((0*(1-Assumptions!$G$110))+C18) -> 29.61 | D24: =((C24*(1-Assumptions!$G$110))+D18) -> 59.448211 | E24: =((D24*(1-Assumptions!$G$110))+E18) -> 89.137148 | F24: =((E24*(1-Assumptions!$G$110))+F18) -> 121.46095 | G24: =((F24*(1-Assumptions!$G$110))+G18) -> 154.14872 | H24: =((G24*(1-Assumptions!$G$110))+H18) -> 187.43328 | I24: =((H24*(1-Assumptions!$G$110))+I18) -> 221.6011 | J24: =((I24*(1-Assumptions!$G$110))+J18) -> 256.94009 | K24: =((J24*(1-Assumptions!$G$110))+K18) -> 293.7411 | ... AL24: =((AK24*(1-Assumptions!$G$110))+AL18) -> 3484.7364
A25: Annual plans billed (new + renewals) | B25: bill_annual | C25: =(C19+0) -> 54.285 | D25: =(D19+0) -> 60.62595 | E25: =(E19+0) -> 66.32049 | F25: =(F19+0) -> 77.08943 | G25: =(G19+0) -> 84.222079 | H25: =(H19+0) -> 91.854359 | I25: =(I19+0) -> 100.13122 | J25: =(J19+0) -> 109.11259 | ... N25: =(N19+0) -> 153.42739 | O25: =(O19+(Assumptions!$G$43*C25)) -> 196.30689 | P25: =(P19+(Assumptions!$G$43*D25)) -> 214.44885 | Q25: =(Q19+(Assumptions!$G$43*E25)) -> 233.51786 | R25: =(R19+(Assumptions!$G$43*F25)) -> 256.71736 | S25: =(S19+(Assumptions!$G$43*G25)) -> 279.46499 | T25: =(T19+(Assumptions!$G$43*H25)) -> 304.13006 | U25: =(U19+(Assumptions!$G$43*I25)) -> 330.93704 | V25: =(V19+(Assumptions!$G$43*J25)) -> 360.07733 | ... AL25: =(AL19+(Assumptions!$G$43*Z25)) -> 1430.2168
A26: Annual-plan subscribers (billed in last 12 months) | B26: subs_annual | C26: =SUM(C25:C25) -> 54.285 | D26: =SUM(C25:D25) -> 114.91095 | E26: =SUM(C25:E25) -> 181.23144 | F26: =SUM(C25:F25) -> 258.32087 | G26: =SUM(C25:G25) -> 342.54295 | H26: =SUM(C25:H25) -> 434.39731 | I26: =SUM(C25:I25) -> 534.52853 | J26: =SUM(C25:J25) -> 643.64112 | K26: =SUM(C25:K25) -> 762.50253 | L26: =SUM(C25:L25) -> 891.94865 | M26: =SUM(C25:M25) -> 1032.8898 | N26: =SUM(C25:N25) -> 1186.3172 | O26: =SUM(D25:O25) -> 1328.3391 | P26: =SUM(E25:P25) -> 1482.162 | Q26: =SUM(F25:Q25) -> 1649.3593 | R26: =SUM(G25:R25) -> 1828.9873 | S26: =SUM(H25:S25) -> 2024.2302 | T26: =SUM(I25:T25) -> 2236.5059 | U26: =SUM(J25:U25) -> 2467.3117 | ... AL26: =SUM(AA25:AL25) -> 11254.576
A27: Student plans billed (new + renewals) | B27: bill_student | C27: =(C20+0) -> 14.805 | D27: =(D20+0) -> 16.53435 | E27: =(E20+0) -> 18.087406 | F27: =(F20+0) -> 21.02439 | G27: =(G20+0) -> 22.969658 | H27: =(H20+0) -> 25.051189 | I27: =(I20+0) -> 27.308516 | J27: =(J20+0) -> 29.757979 | ... N27: =(N20+0) -> 41.843833 | O27: =(O20+(Assumptions!$G$44*C27)) -> 52.205794 | P27: =(P20+(Assumptions!$G$44*D27)) -> 56.997959 | Q27: =(Q20+(Assumptions!$G$44*E27)) -> 62.058822 | R27: =(R20+(Assumptions!$G$44*F27)) -> 68.121631 | S27: =(S20+(Assumptions!$G$44*G27)) -> 74.150455 | T27: =(T20+(Assumptions!$G$44*H27)) -> 80.689956 | U27: =(U20+(Assumptions!$G$44*I27)) -> 87.797791 | V27: =(V20+(Assumptions!$G$44*J27)) -> 95.524689 | ... AL27: =(AL20+(Assumptions!$G$44*Z27)) -> 375.98375
